<?xml version="1.0" ?>
<!-- =================================================================================== -->
<!-- |    This document was autogenerated by xacro from /home/q/ros1/cobot_kit/cobot_s/cobot_v5/agilex_ws/src/moveit_config/cobot_description/urdf/cobot_description_v2.xacro | -->
<!-- |    EDITING THIS FILE BY HAND IS NOT RECOMMENDED                                 | -->
<!-- =================================================================================== -->
<!-- This URDF was automatically created by SolidWorks to URDF Exporter! Originally created by Stephen Brawner (brawner@gmail.com) 
     Commit Version: 1.6.0-1-g15f4949  Build Version: 1.6.7594.29634
     For more information, please see http://wiki.ros.org/sw_urdf_exporter -->
<robot name="cobot_description">
    <link name="dh_robotics_ag95_base_link">
        <inertial>
            <origin rpy="0 0 0" xyz="0 0 0" />
            <mass value="0.22652" />
            <inertia ixx="0.00020005" ixy="-4.2442E-10" ixz="-2.9069E-10" iyy="0.00017832" iyz="-3.4402E-08" izz="0.00013478" />
        </inertial>
        <visual>
            <origin rpy="0 0 0" xyz="0 0 0" />
            <geometry>
                <mesh filename="package://dh_robotics_ag95_model/meshes/base_link.STL" scale="1 1 1" />
            </geometry>
            <material name="">
                <color rgba="0.1 0.1 0.1 1" />
            </material>
        </visual>
        <collision>
            <origin rpy="0 0 0" xyz="0 0 0" />
            <geometry>
                <mesh filename="package://dh_robotics_ag95_model/meshes/base_link.STL" />
            </geometry>
        </collision>
    </link>
    <link name="left_crank">
        <inertial>
            <origin rpy="0 0 0" xyz="-0.000200000000003065 0.0199435877845359 0.0292245259211331" />
            <mass value="0.00853198276973456" />
            <inertia ixx="2.89328108496468E-06" ixy="-1.57935047237397E-19" ixz="-1.93980378593255E-19" iyy="1.86719750325683E-06" iyz="-1.21858577871576E-06" izz="1.21905238907251E-06" />
        </inertial>
        <visual>
            <origin rpy="0 0 0" xyz="0 0 0" />
            <geometry>
                <mesh filename="package://dh_robotics_ag95_model/meshes/link_crank.STL" scale="1 1 1" />
            </geometry>
            <material name="">
                <color rgba="0.1 0.1 0.1 1" />
            </material>
        </visual>
        <collision>
            <origin rpy="0 0 0" xyz="0 0 0" />
            <geometry>
                <mesh filename="package://dh_robotics_ag95_model/meshes/link_crank.STL" scale="1 1 1" />
            </geometry>
        </collision>
    </link>
    <link name="left_rod">
        <inertial>
            <origin rpy="0 0 0" xyz="0.00030115855001899 0.0373907951953854 -0.0208027427000385" />
            <mass value="0.022614240507152" />
            <inertia ixx="1.52518312458174E-05" ixy="9.76583423954399E-10" ixz="-5.43838577022588E-10" iyy="6.17694243867776E-06" iyz="6.78636130740228E-06" izz="1.16494917907219E-05" />
        </inertial>
        <visual>
            <origin rpy="0 0 0" xyz="0 0 0" />
            <geometry>
                <mesh filename="package://dh_robotics_ag95_model/meshes/link_rod.STL" scale="1 1 1" />
            </geometry>
            <material name="">
                <color rgba="0.1 0.1 0.1 1" />
            </material>
        </visual>
        <collision>
            <origin rpy="0 0 0" xyz="0 0 0" />
            <geometry>
                <mesh filename="package://dh_robotics_ag95_model/meshes/link_rod.STL" scale="1 1 1" />
            </geometry>
        </collision>
    </link>
    <link name="left_distal_phalanx">
        <inertial>
            <origin rpy="0 0 0" xyz="0.000299999999999317 0.0160078233491243 -0.0136945669206257" />
            <mass value="0.0104003125914103" />
            <inertia ixx="2.71909453810972E-06" ixy="1.35402465472579E-21" ixz="-7.1817349065269E-22" iyy="7.69100314106116E-07" iyz="6.74715432769696E-07" izz="2.30315190420171E-06" />
        </inertial>
        <visual>
            <origin rpy="0 0 0" xyz="0 0 0" />
            <geometry>
                <mesh filename="package://dh_robotics_ag95_model/meshes/link_distal_phalanx.STL" scale="1 1 1" />
            </geometry>
            <material name="">
                <color rgba="0.792156862745098 0.819607843137255 0.933333333333333 1" />
            </material>
        </visual>
        <collision>
            <origin rpy="0 0 0" xyz="0 0 0" />
            <geometry>
                <mesh filename="package://dh_robotics_ag95_model/meshes/link_distal_phalanx.STL" scale="1 1 1" />
            </geometry>
        </collision>
    </link>
    <link name="left_proximal_phalanx">
        <inertial>
            <origin rpy="0 0 0" xyz="0.000123011831763771 0.0507850843201817 0.00103968640075166" />
            <mass value="0.0271177346495152" />
            <inertia ixx="2.61910379223783E-05" ixy="-2.43616858946494E-07" ixz="-6.37789906117123E-09" iyy="2.8270243746167E-06" iyz="-5.37200748039765E-07" izz="2.83695868220296E-05" />
        </inertial>
        <visual>
            <origin rpy="0 0 0" xyz="0 0 0" />
            <geometry>
                <mesh filename="package://dh_robotics_ag95_model/meshes/link_proximal_phalanx.STL" scale="1 1 1" />
            </geometry>
            <material name="">
                <color rgba="0.1 0.1 0.1 1" />
            </material>
        </visual>
        <collision>
            <origin rpy="0 0 0" xyz="0 0 0" />
            <geometry>
                <mesh filename="package://dh_robotics_ag95_model/meshes/link_proximal_phalanx.STL" scale="1 1 1" />
            </geometry>
        </collision>
    </link>
    <link name="right_crank">
        <inertial>
            <origin rpy="0 0 0" xyz="-0.000200000000003065 0.0199435877845359 0.0292245259211331" />
            <mass value="0.00853198276973456" />
            <inertia ixx="2.89328108496468E-06" ixy="-1.57935047237397E-19" ixz="-1.93980378593255E-19" iyy="1.86719750325683E-06" iyz="-1.21858577871576E-06" izz="1.21905238907251E-06" />
        </inertial>
        <visual>
            <origin rpy="0 0 0" xyz="0 0 0" />
            <geometry>
                <mesh filename="package://dh_robotics_ag95_model/meshes/link_crank.STL" scale="1 1 1" />
            </geometry>
            <material name="">
                <color rgba="0.1 0.1 0.1 1" />
            </material>
        </visual>
        <collision>
            <origin rpy="0 0 0" xyz="0 0 0" />
            <geometry>
                <mesh filename="package://dh_robotics_ag95_model/meshes/link_crank.STL" scale="1 1 1" />
            </geometry>
        </collision>
    </link>
    <link name="right_rod">
        <inertial>
            <origin rpy="0 0 0" xyz="0.00030115855001899 0.0373907951953854 -0.0208027427000385" />
            <mass value="0.022614240507152" />
            <inertia ixx="1.52518312458174E-05" ixy="9.76583423954399E-10" ixz="-5.43838577022588E-10" iyy="6.17694243867776E-06" iyz="6.78636130740228E-06" izz="1.16494917907219E-05" />
        </inertial>
        <visual>
            <origin rpy="0 0 0" xyz="0 0 0" />
            <geometry>
                <mesh filename="package://dh_robotics_ag95_model/meshes/link_rod.STL" scale="1 1 1" />
            </geometry>
            <material name="">
                <color rgba="0.1 0.1 0.1 1" />
            </material>
        </visual>
        <collision>
            <origin rpy="0 0 0" xyz="0 0 0" />
            <geometry>
                <mesh filename="package://dh_robotics_ag95_model/meshes/link_rod.STL" scale="1 1 1" />
            </geometry>
        </collision>
    </link>
    <link name="right_distal_phalanx">
        <inertial>
            <origin rpy="0 0 0" xyz="0.000299999999999317 0.0160078233491243 -0.0136945669206257" />
            <mass value="0.0104003125914103" />
            <inertia ixx="2.71909453810972E-06" ixy="1.35402465472579E-21" ixz="-7.1817349065269E-22" iyy="7.69100314106116E-07" iyz="6.74715432769696E-07" izz="2.30315190420171E-06" />
        </inertial>
        <visual>
            <origin rpy="0 0 0" xyz="0 0 0" />
            <geometry>
                <mesh filename="package://dh_robotics_ag95_model/meshes/link_distal_phalanx.STL" scale="1 1 1" />
            </geometry>
            <material name="">
                <color rgba="0.792156862745098 0.819607843137255 0.933333333333333 1" />
            </material>
        </visual>
        <collision>
            <origin rpy="0 0 0" xyz="0 0 0" />
            <geometry>
                <mesh filename="package://dh_robotics_ag95_model/meshes/link_distal_phalanx.STL" scale="1 1 1" />
            </geometry>
        </collision>
    </link>
    <link name="right_proximal_phalanx">
        <inertial>
            <origin rpy="0 0 0" xyz="0.000123011831763771 0.0507850843201817 0.00103968640075166" />
            <mass value="0.0271177346495152" />
            <inertia ixx="2.61910379223783E-05" ixy="-2.43616858946494E-07" ixz="-6.37789906117123E-09" iyy="2.8270243746167E-06" iyz="-5.37200748039765E-07" izz="2.83695868220296E-05" />
        </inertial>
        <visual>
            <origin rpy="0 0 0" xyz="0 0 0" />
            <geometry>
                <mesh filename="package://dh_robotics_ag95_model/meshes/link_proximal_phalanx.STL" scale="1 1 1" />
            </geometry>
            <material name="">
                <color rgba="0.1 0.1 0.1 1" />
            </material>
        </visual>
        <collision>
            <origin rpy="0 0 0" xyz="0 0 0" />
            <geometry>
                <mesh filename="package://dh_robotics_ag95_model/meshes/link_proximal_phalanx.STL" scale="1 1 1" />
            </geometry>
        </collision>
    </link>
    <joint name="finger_joint" type="revolute">
        <origin rpy="-0.6523  0 0 " xyz="0 0.016 0.10586 " />
        <parent link="dh_robotics_ag95_base_link" />
        <child link="left_crank" />
        <axis xyz="1 0 0" />
        <limit effort="1000" lower="0" upper="0.6524" velocity="1.0" />
    </joint>
    <joint name="left_rod_joint" type="revolute">
        <origin rpy="0.29795 0 0" xyz="0 0.037 0" />
        <parent link="left_crank" />
        <child link="left_rod" />
        <axis xyz="1 0 0" />
        <limit effort="1000" lower="-1" upper="0" velocity="1.0" />
        <mimic joint="finger_joint" multiplier="0.4563942" offset="0" />
    </joint>
    <joint name="left_proximal_phalanx_joint" type="revolute">
        <origin rpy="-0.801 0 0.0" xyz="0 0.016 0.10586" />
        --&gt;
        <parent link="dh_robotics_ag95_base_link" />
        <child link="left_proximal_phalanx" />
        <axis xyz="1 0 0" />
        <limit effort="1000" lower="0" upper="0.8757" velocity="1.0" />
        <mimic joint="finger_joint" multiplier="1.451855" offset="0" />
    </joint>
    <joint name="left_distal_phalanx_joint" type="revolute">
        <origin rpy="0.0132645 0 0" xyz="0 0 0.06083" />
        <parent link="left_rod" />
        <child link="left_distal_phalanx" />
        <axis xyz="1 0 0" />
        <limit effort="1000" lower="-1" upper="0" velocity="1.0" />
        <mimic joint="finger_joint" multiplier="-1.4563851" offset="0" />
    </joint>
    <joint name="right_crank_joint" type="revolute">
        <origin rpy="-0.6523  0 3.141592653589793 " xyz="0 -0.016 0.10586 " />
        <parent link="dh_robotics_ag95_base_link" />
        <child link="right_crank" />
        <axis xyz="1 0 0" />
        <limit effort="1000" lower="0" upper="0.6524" velocity="1.0" />
        <mimic joint="finger_joint" multiplier="1" offset="0" />
    </joint>
    <joint name="right_rod_joint" type="revolute">
        <origin rpy="0.29795 0 0" xyz="0 0.037 0" />
        <parent link="right_crank" />
        <child link="right_rod" />
        <axis xyz="1 0 0" />
        <limit effort="1000" lower="-1" upper="0" velocity="1.0" />
        <mimic joint="finger_joint" multiplier="0.4563942" offset="0" />
    </joint>
    <joint name="right_proximal_phalanx_joint" type="revolute">
        <origin rpy="-0.801 0 3.141592653589793" xyz="0 -0.016 0.10586" />
        --&gt;
        <parent link="dh_robotics_ag95_base_link" />
        <child link="right_proximal_phalanx" />
        <axis xyz="1 0 0" />
        <limit effort="1000" lower="0" upper="0.8757" velocity="1.0" />
        <mimic joint="finger_joint" multiplier="1.451855" offset="0" />
    </joint>
    <joint name="right_distal_phalanx_joint" type="revolute">
        <origin rpy="0.0132645 0 0" xyz="0 0 0.06083" />
        <parent link="right_rod" />
        <child link="right_distal_phalanx" />
        <axis xyz="1 0 0" />
        <limit effort="1000" lower="-1" upper="0" velocity="1.0" />
        <mimic joint="finger_joint" multiplier="-1.4563851" offset="0" />
    </joint>
    <transmission name="finger_joint_trans">
        <type>transmission_interface/SimpleTransmission</type>
        <joint name="finger_joint">
            <hardwareInterface>PositionJointInterface</hardwareInterface>
        </joint>
        <actuator name="finger_joint_motor">
            <mechanicalReduction>1</mechanicalReduction>
            <hardwareInterface>hardware_interface/EffortJointInterface</hardwareInterface>
        </actuator>
    </transmission>
    <link name="Link1">
        <inertial>
            <origin rpy="0 0 0" xyz="1.2226305431569E-08 0.0211079974844683 -0.0251854220842269" />
            <mass value="0.593563443690403" />
            <inertia ixx="0.00126614120341847" ixy="-1.294980943835E-08" ixz="-9.80120923066996E-09" iyy="0.00118168178300364" iyz="-0.00021121727444415" izz="0.00056135241627747" />
        </inertial>
        <visual>
            <origin rpy="0 0 0" xyz="0 0 0" />
            <geometry>
                <mesh filename="package://cobot_description/meshes/RM65/link1.STL" />
            </geometry>
            <material name="">
                <color rgba="1 1 1 1" />
            </material>
        </visual>
        <collision>
            <origin rpy="0 0 0" xyz="0 0 0" />
            <geometry>
                <mesh filename="package://cobot_description/meshes/RM65/link1.STL" />
            </geometry>
        </collision>
    </link>
    <joint name="joint1" type="revolute">
        <origin rpy="0 -1.57 0" xyz="-0.218 0 -0.06" />
        <parent link="Link7" />
        <child link="Link1" />
        <axis xyz="0 0 1" />
        <limit effort="60" lower="-3.1" upper="3.1" velocity="3.14" />
        <dynamics damping="50" friction="1" />
    </joint>
    <link name="Link2">
        <inertial>
            <origin rpy="0 0 0" xyz="0.152256463426163 4.75383656106654E-07 -0.00620260383607792" />
            <mass value="0.864175046869043" />
            <inertia ixx="0.00089150298478414" ixy="-2.23268489334765E-08" ixz="0.00156246461035015" iyy="0.00733754343083901" iyz="6.28110889329165E-09" izz="0.00697869103915473" />
        </inertial>
        <visual>
            <origin rpy="0 0 0" xyz="0 0 0" />
            <geometry>
                <mesh filename="package://cobot_description/meshes/RM65/link2.STL" />
            </geometry>
            <material name="">
                <color rgba="1 1 1 1" />
            </material>
        </visual>
        <collision>
            <origin rpy="0 0 0" xyz="0 0 0" />
            <geometry>
                <mesh filename="package://cobot_description/meshes/RM65/link2.STL" />
            </geometry>
        </collision>
    </link>
    <joint name="joint2" type="revolute">
        <origin rpy="1.5708 -1.5708 0" xyz="0 0 0" />
        <parent link="Link1" />
        <child link="Link2" />
        <axis xyz="0 0 1" />
        <limit effort="60" lower="-2.268" upper="2.268" velocity="3.14" />
        <dynamics damping="50" friction="1" />
    </joint>
    <link name="Link3">
        <inertial>
            <origin rpy="0 0 0" xyz="5.05312670989961E-06 -0.0595925663694732 0.010569069212336" />
            <mass value="0.289633681624654" />
            <inertia ixx="0.00063737100450158" ixy="-7.05261293649751E-08" ixz="-3.86643272239426E-08" iyy="0.00015648388095025" iyz="-0.00014461035994916" izz="0.000614178164773085" />
        </inertial>
        <visual>
            <origin rpy="0 0 0" xyz="0 0 0" />
            <geometry>
                <mesh filename="package://cobot_description/meshes/RM65/link3.STL" />
            </geometry>
            <material name="">
                <color rgba="1 1 1 1" />
            </material>
        </visual>
        <collision>
            <origin rpy="0 0 0" xyz="0 0 0" />
            <geometry>
                <mesh filename="package://cobot_description/meshes/RM65/link3.STL" />
            </geometry>
        </collision>
    </link>
    <joint name="joint3" type="revolute">
        <origin rpy="0 0 1.5708" xyz="0.256 0 0" />
        <parent link="Link2" />
        <child link="Link3" />
        <axis xyz="0 0 1" />
        <limit effort="30" lower="-2.355" upper="2.355" velocity="3.92" />
        <dynamics damping="50" friction="1" />
    </joint>
    <link name="Link4">
        <inertial>
            <origin rpy="0 0 0" xyz="1.15516617405898E-06 -0.0180424468598241 -0.0215394748352687" />
            <mass value="0.239419768320061" />
            <inertia ixx="0.000285938919722783" ixy="3.07101359163101E-09" ixz="-2.21994118981953E-09" iyy="0.000262727540304212" iyz="4.4236583260078E-05" izz="0.000119888082791859" />
        </inertial>
        <visual>
            <origin rpy="0 0 0" xyz="0 0 0" />
            <geometry>
                <mesh filename="package://cobot_description/meshes/RM65/link4.STL" />
            </geometry>
            <material name="">
                <color rgba="1 1 1 1" />
            </material>
        </visual>
        <collision>
            <origin rpy="0 0 0" xyz="0 0 0" />
            <geometry>
                <mesh filename="package://cobot_description/meshes/RM65/link4.STL" />
            </geometry>
        </collision>
    </link>
    <joint name="joint4" type="revolute">
        <origin rpy="1.5708 0 0" xyz="0 -0.21 0" />
        <parent link="Link3" />
        <child link="Link4" />
        <axis xyz="0 0 1" />
        <limit effort="10" lower="-3.1" upper="3.1" velocity="3.92" />
        <dynamics damping="50" friction="1" />
    </joint>
    <link name="Link5">
        <inertial>
            <origin rpy="0 0 0" xyz="3.19794786262152E-06 -0.0593808368101458 0.00736804250989326" />
            <mass value="0.218799761431678" />
            <inertia ixx="0.000350540363914072" ixy="-3.41781619975602E-08" ixz="-1.77056457224373E-08" iyy="0.000104927867487581" iyz="-7.82431228461971E-05" izz="0.000334482418423629" />
        </inertial>
        <visual>
            <origin rpy="0 0 0" xyz="0 0 0" />
            <geometry>
                <mesh filename="package://cobot_description/meshes/RM65/link5.STL" />
            </geometry>
            <material name="">
                <color rgba="1 1 1 1" />
            </material>
        </visual>
        <collision>
            <origin rpy="0 0 0" xyz="0 0 0" />
            <geometry>
                <mesh filename="package://cobot_description/meshes/RM65/link5.STL" />
            </geometry>
        </collision>
    </link>
    <joint name="joint5" type="revolute">
        <origin rpy="-1.5708 0 0" xyz="0 0 0" />
        <parent link="Link4" />
        <child link="Link5" />
        <axis xyz="0 0 1" />
        <limit effort="10" lower="-2.233" upper="2.233" velocity="3.92" />
        <dynamics damping="50" friction="1" />
    </joint>
    <link name="Link6">
        <inertial>
            <origin rpy="0 0 0" xyz="0.000714234511756999 -0.000396718732824521 -0.0126723660946126" />
            <mass value="0.0649018034311231" />
            <inertia ixx="2.02766547502765E-05" ixy="-1.32505200276849E-06" ixz="-2.5845091522508E-08" iyy="1.87986725225022E-05" iyz="3.39471452125439E-09" izz="3.17885459163081E-05" />
        </inertial>
        <visual>
            <origin rpy="0 0 0" xyz="0 0 0" />
            <geometry>
                <mesh filename="package://cobot_description/meshes/RM65/link6.STL" />
            </geometry>
            <material name="">
                <color rgba="1 1 1 1" />
            </material>
        </visual>
        <collision>
            <origin rpy="0 0 0" xyz="0 0 0" />
            <geometry>
                <mesh filename="package://cobot_description/meshes/RM65/link6.STL" />
            </geometry>
        </collision>
    </link>
    <joint name="joint6" type="revolute">
        <origin rpy="1.5708 0 0" xyz="0 -0.144 0" />
        <parent link="Link5" />
        <child link="Link6" />
        <axis xyz="0 0 1" />
        <limit effort="10" lower="-6.28" upper="6.28" velocity="3.92" />
        <dynamics damping="50" friction="1" />
    </joint>
    <transmission name="tran1">
        <type>transmission_interface/SimpleTransmission</type>
        <joint name="joint1">
            <hardwareInterface>hardware_interface/PositionJointInterface</hardwareInterface>
        </joint>
        <actuator name="motor1">
            <hardwareInterface>hardware_interface/PositionJointInterface</hardwareInterface>
            <mechanicalReduction>1</mechanicalReduction>
        </actuator>
    </transmission>
    <transmission name="tran1">
        <type>transmission_interface/SimpleTransmission</type>
        <joint name="joint2">
            <hardwareInterface>hardware_interface/PositionJointInterface</hardwareInterface>
        </joint>
        <actuator name="motor1">
            <hardwareInterface>hardware_interface/PositionJointInterface</hardwareInterface>
            <mechanicalReduction>1</mechanicalReduction>
        </actuator>
    </transmission>
    <transmission name="tran1">
        <type>transmission_interface/SimpleTransmission</type>
        <joint name="joint3">
            <hardwareInterface>hardware_interface/PositionJointInterface</hardwareInterface>
        </joint>
        <actuator name="motor1">
            <hardwareInterface>hardware_interface/PositionJointInterface</hardwareInterface>
            <mechanicalReduction>1</mechanicalReduction>
        </actuator>
    </transmission>
    <transmission name="tran1">
        <type>transmission_interface/SimpleTransmission</type>
        <joint name="joint4">
            <hardwareInterface>hardware_interface/PositionJointInterface</hardwareInterface>
        </joint>
        <actuator name="motor1">
            <hardwareInterface>hardware_interface/PositionJointInterface</hardwareInterface>
            <mechanicalReduction>1</mechanicalReduction>
        </actuator>
    </transmission>
    <transmission name="tran1">
        <type>transmission_interface/SimpleTransmission</type>
        <joint name="joint5">
            <hardwareInterface>hardware_interface/PositionJointInterface</hardwareInterface>
        </joint>
        <actuator name="motor1">
            <hardwareInterface>hardware_interface/PositionJointInterface</hardwareInterface>
            <mechanicalReduction>1</mechanicalReduction>
        </actuator>
    </transmission>
    <transmission name="tran1">
        <type>transmission_interface/SimpleTransmission</type>
        <joint name="joint6">
            <hardwareInterface>hardware_interface/PositionJointInterface</hardwareInterface>
        </joint>
        <actuator name="motor1">
            <hardwareInterface>hardware_interface/PositionJointInterface</hardwareInterface>
            <mechanicalReduction>1</mechanicalReduction>
        </actuator>
    </transmission>
    <!-- ros_control plugin -->
    <gazebo>
        <plugin filename="libgazebo_ros_control.so" name="gazebo_ros_control">
            <robotNamespace>/arm</robotNamespace>
            <robotSimType>gazebo_ros_control/DefaultRobotHWSim</robotSimType>
            <legacyModeNS>true</legacyModeNS>
        </plugin>
    </gazebo>
    <link name="base_footprint" />
    <link name="base_link">
        <inertial>
            <origin rpy="0 0 0" xyz="-0.18605 0.0010457 0.13419" />
            <mass value="35.137" />
            <inertia ixx="0.52213" ixy="0.00028039" ixz="-0.0048629" iyy="1.0698" iyz="-0.0011677" izz="1.4095" />
        </inertial>
        <visual>
            <origin rpy="0 0 3.14" xyz="0 0 0" />
            <geometry>
                <mesh filename="package://cobot_description/meshes/base_link.STL" />
            </geometry>
            <material name="">
                <color rgba="0.77647 0.77647 0.81961 1" />
            </material>
        </visual>
        <collision>
            <origin rpy="0 0 0" xyz="0 0 0" />
            <geometry>
                <mesh filename="package://cobot_description/meshes/base_link.STL" />
            </geometry>
        </collision>
    </link>
    <joint name="base_link" type="fixed">
        <origin rpy="0 0 0" xyz="0.201 0 0.072" />
        <parent link="base_footprint" />
        <child link="base_link" />
        <axis xyz="0 0 0" />
    </joint>
    <link name="front_lidar">
        <inertial>
            <origin rpy="0 0 0" xyz="-0.00016986 -2.2612E-10 0.018642" />
            <mass value="0.15478" />
            <inertia ixx="6.9567E-05" ixy="-1.7298E-12" ixz="-4.6381E-07" iyy="7.1065E-05" iyz="-5.4415E-13" izz="9.8843E-05" />
        </inertial>
        <visual>
            <origin rpy="0 0 0" xyz="0 0 0" />
            <geometry>
                <mesh filename="package://cobot_description/meshes/front_lidar.STL" />
            </geometry>
            <material name="">
                <color rgba="1 1 1 1" />
            </material>
        </visual>
        <collision>
            <origin rpy="0 0 0" xyz="0 0 0" />
            <geometry>
                <mesh filename="package://cobot_description/meshes/front_lidar.STL" />
            </geometry>
        </collision>
    </link>
    <joint name="front_lidar_joint" type="fixed">
        <origin rpy="0 0 0" xyz="0.30 0 0.214" />
        <parent link="base_link" />
        <child link="front_lidar" />
        <axis xyz="0 0 0" />
    </joint>
    <link name="arm_base">
        <inertial>
            <origin rpy="0 0 0" xyz="-0.024179 0.0061525 0.44341" />
            <mass value="8.0743" />
            <inertia ixx="0.080601" ixy="4.9995E-05" ixz="0.00052048" iyy="0.077325" iyz="-2.0984E-05" izz="0.024026" />
        </inertial>
        <visual>
            <origin rpy="0 0 0" xyz="0 0 0" />
            <geometry>
                <mesh filename="package://cobot_description/meshes/arm_base.STL" />
            </geometry>
            <material name="">
                <color rgba="0.69804 0.69804 0.69804 1" />
            </material>
        </visual>
        <collision>
            <origin rpy="0 0 0" xyz="0 0 0" />
            <geometry>
                <mesh filename="package://cobot_description/meshes/arm_base.STL" />
            </geometry>
        </collision>
    </link>
    <joint name="arm_base" type="fixed">
        <origin rpy="0 0 0" xyz="0.101 0 0.16" />
        <parent link="base_link" />
        <child link="arm_base" />
        <axis xyz="0 0 0" />
    </joint>
    <link name="Link7">
        <inertial>
            <origin rpy="0 0 0" xyz="-0.016412 0.00026497 -0.060445" />
            <mass value="0.53096" />
            <inertia ixx="0.00096525" ixy="1.49E-05" ixz="-1.7049E-05" iyy="0.0018872" iyz="1.0632E-06" izz="0.0018331" />
        </inertial>
        <visual>
            <origin rpy="0 0 0" xyz="0 0 0" />
            <geometry>
                <mesh filename="package://cobot_description/meshes/Link7.STL" />
            </geometry>
            <material name="">
                <color rgba="1 1 1 1" />
            </material>
        </visual>
        <collision>
            <origin rpy="0 0 0" xyz="0 0 0" />
            <geometry>
                <mesh filename="package://cobot_description/meshes/Link7.STL" />
            </geometry>
        </collision>
    </link>
    <joint name="joint_arm_rotary" type="revolute">
        <origin rpy="3.1416 0 -3.1416" xyz="0 0 0.4878" />
        <parent link="arm_base" />
        <child link="Link7" />
        <axis xyz="0 0 -1" />
        <limit effort="300" lower="-3.49" upper="0.5" velocity="3.14" />
        <dynamics damping="50" friction="1" />
    </joint>
    <joint name="hand_joint" type="fixed">
        <origin rpy="0 0 0" xyz="0 0 0.018" />
        <parent link="Link6" />
        <child link="dh_robotics_ag95_base_link" />
    </joint>
    <link name="hand_camera">
        <inertial>
            <origin rpy="0 0 0" xyz="0.0009804 0.025556 -0.036977" />
            <mass value="0.067926" />
            <inertia ixx="3.7811E-05" ixy="2.2861E-18" ixz="2.2446E-19" iyy="9.4061E-05" iyz="6.1172E-06" izz="0.00012345" />
        </inertial>
        <visual>
            <origin rpy="0 0 0" xyz="0 0 0" />
            <geometry>
                <box size="0.02 0.05 0.02" />
            </geometry>
            <material name="">
                <color rgba="1 1 1 1" />
            </material>
        </visual>
        <collision>
            <origin rpy="0 0 0" xyz="0 0 0" />
            <geometry>
                <box size="0.02 0.05 0.02" />
            </geometry>
        </collision>
    </link>
    <joint name="hand_camera_joint" type="fixed">
        <origin rpy="0 0 0" xyz="-0.1 0 0.04" />
        <parent link="Link6" />
        <child link="hand_camera" />
        <axis xyz="0 0 0" />
    </joint>
    <link name="head_Link">
        <inertial>
            <origin rpy="0 0 0" xyz="-0.013341 -0.0030001 0.14378" />
            <mass value="0.10888" />
            <inertia ixx="0.00015548" ixy="5.612E-11" ixz="7.7393E-06" iyy="6.2021E-05" iyz="-3.4676E-10" izz="0.00016861" />
        </inertial>
        <visual>
            <origin rpy="0 0 0" xyz="0 0 0" />
            <geometry>
                <mesh filename="package://cobot_description/meshes/head_Link.STL" />
            </geometry>
            <material name="">
                <color rgba="1 1 1 1" />
            </material>
        </visual>
        <collision>
            <origin rpy="0 0 0" xyz="0 0 0" />
            <geometry>
                <mesh filename="package://cobot_description/meshes/head_Link.STL" />
            </geometry>
        </collision>
    </link>
    <joint name="head_joint" type="fixed">
        <origin rpy="0 0 3.1416" xyz="0.10013 0 1.1628" />
        <parent link="base_link" />
        <child link="head_Link" />
        <axis xyz="0 0 0" />
    </joint>
    <link name="display_Link">
        <collision>
            <origin rpy="0 0 0" xyz="0 0 0" />
            <geometry>
                <box size="0.03 0.3 0.2" />
            </geometry>
        </collision>
        <inertial>
            <mass value="0.1" />
            <origin xyz="0 0 0" rpy="0 0 0" />
            <inertia ixx="0.03" iyy="0.03" izz="0.03" ixy="0.0" ixz="0.0" iyz="0.0" />
        </inertial>
    </link>
    <joint name="display_joint" type="fixed">
        <origin rpy="0 0 0" xyz="0.15 0 -0.1" />
        <parent link="head_Link" />
        <child link="display_Link" />
        <axis xyz="0 0 0" />
    </joint>
    <link name="head_camera">
        <inertial>
            <origin rpy="0 0 0" xyz="0.027537 -0.14823 -1.1256" />
            <mass value="91.96" />
            <inertia ixx="16.389" ixy="0.28606" ixz="-0.57062" iyy="13.534" iyz="-2.6339" izz="7.1915" />
        </inertial>
        <visual>
            <origin rpy="0 0 0" xyz="0 0 0" />
            <geometry>
                <mesh filename="package://cobot_description/meshes/head_camera.STL" />
            </geometry>
            <material name="">
                <color rgba="1 1 1 1" />
            </material>
        </visual>
        <collision>
            <origin rpy="0 0 0" xyz="0 0 0" />
            <geometry>
                <mesh filename="package://cobot_description/meshes/head_camera.STL" />
            </geometry>
        </collision>
    </link>
    <joint name="head_camera_joint" type="fixed">
        <origin rpy="0.066568 0 1.5708" xyz="-0.033687 -0.0039804 0.18195" />
        <parent link="head_Link" />
        <child link="head_camera" />
        <axis xyz="0 0 0" />
    </joint>
    <link name="basket_Link">
        <inertial>
            <origin rpy="0 0 0" xyz="-4.1633E-16 -4.4913E-14 0.021251" />
            <mass value="0.39699" />
            <inertia ixx="0.0056399" ixy="-2.6074E-10" ixz="5.7967E-18" iyy="0.0033409" iyz="1.9651E-17" izz="0.0081811" />
        </inertial>
        <visual>
            <origin rpy="0 0 0" xyz="0 0 0" />
            <geometry>
                <box size="0.24 0.5 0.2" />
            </geometry>
            <material name="">
                <color rgba="0.69804 0.69804 0.69804 1" />
            </material>
        </visual>
        <collision>
            <origin rpy="0 0 0" xyz="0 0 0" />
            <geometry>
                <box size="0.1 0.1 0.1" />
            </geometry>
        </collision>
    </link>
    <joint name="basket_joint" type="fixed">
        <origin rpy="0 0 0" xyz="-0.21 0 0.26" />
        <parent link="base_link" />
        <child link="basket_Link" />
        <axis xyz="0 0 0" />
    </joint>
    <transmission name="trans_left_rod_joint">
        <type>transmission_interface/SimpleTransmission</type>
        <joint name="left_rod_joint">
            <hardwareInterface>hardware_interface/EffortJointInterface</hardwareInterface>
        </joint>
        <actuator name="left_rod_joint_motor">
            <hardwareInterface>hardware_interface/EffortJointInterface</hardwareInterface>
            <mechanicalReduction>1</mechanicalReduction>
        </actuator>
    </transmission>
    <transmission name="trans_left_proximal_phalanx_joint">
        <type>transmission_interface/SimpleTransmission</type>
        <joint name="left_proximal_phalanx_joint">
            <hardwareInterface>hardware_interface/EffortJointInterface</hardwareInterface>
        </joint>
        <actuator name="left_proximal_phalanx_joint_motor">
            <hardwareInterface>hardware_interface/EffortJointInterface</hardwareInterface>
            <mechanicalReduction>1</mechanicalReduction>
        </actuator>
    </transmission>
    <transmission name="trans_left_distal_phalanx_joint">
        <type>transmission_interface/SimpleTransmission</type>
        <joint name="left_distal_phalanx_joint">
            <hardwareInterface>hardware_interface/EffortJointInterface</hardwareInterface>
        </joint>
        <actuator name="left_distal_phalanx_joint_motor">
            <hardwareInterface>hardware_interface/EffortJointInterface</hardwareInterface>
            <mechanicalReduction>1</mechanicalReduction>
        </actuator>
    </transmission>
    <transmission name="trans_right_crank_joint">
        <type>transmission_interface/SimpleTransmission</type>
        <joint name="right_crank_joint">
            <hardwareInterface>hardware_interface/EffortJointInterface</hardwareInterface>
        </joint>
        <actuator name="right_crank_joint_motor">
            <hardwareInterface>hardware_interface/EffortJointInterface</hardwareInterface>
            <mechanicalReduction>1</mechanicalReduction>
        </actuator>
    </transmission>
    <transmission name="trans_right_rod_joint">
        <type>transmission_interface/SimpleTransmission</type>
        <joint name="right_rod_joint">
            <hardwareInterface>hardware_interface/EffortJointInterface</hardwareInterface>
        </joint>
        <actuator name="right_rod_joint_motor">
            <hardwareInterface>hardware_interface/EffortJointInterface</hardwareInterface>
            <mechanicalReduction>1</mechanicalReduction>
        </actuator>
    </transmission>
    <transmission name="trans_right_proximal_phalanx_joint">
        <type>transmission_interface/SimpleTransmission</type>
        <joint name="right_proximal_phalanx_joint">
            <hardwareInterface>hardware_interface/EffortJointInterface</hardwareInterface>
        </joint>
        <actuator name="right_proximal_phalanx_joint_motor">
            <hardwareInterface>hardware_interface/EffortJointInterface</hardwareInterface>
            <mechanicalReduction>1</mechanicalReduction>
        </actuator>
    </transmission>
    <transmission name="trans_right_distal_phalanx_joint">
        <type>transmission_interface/SimpleTransmission</type>
        <joint name="right_distal_phalanx_joint">
            <hardwareInterface>hardware_interface/EffortJointInterface</hardwareInterface>
        </joint>
        <actuator name="right_distal_phalanx_joint_motor">
            <hardwareInterface>hardware_interface/EffortJointInterface</hardwareInterface>
            <mechanicalReduction>1</mechanicalReduction>
        </actuator>
    </transmission>
    <transmission name="trans_joint_arm_rotary">
        <type>transmission_interface/SimpleTransmission</type>
        <joint name="joint_arm_rotary">
            <hardwareInterface>hardware_interface/EffortJointInterface</hardwareInterface>
        </joint>
        <actuator name="joint_arm_rotary_motor">
            <hardwareInterface>hardware_interface/EffortJointInterface</hardwareInterface>
            <mechanicalReduction>1</mechanicalReduction>
        </actuator>
    </transmission>
</robot>

